{"timestamp":"2025-07-23T22:03:08.876992","level":"info","event":"DAG bundles loaded: dags-folder","logger":"airflow.dag_processing.bundles.manager.DagBundlesManager"}
{"timestamp":"2025-07-23T22:03:08.878310","level":"info","event":"Filling up the DagBag from /opt/airflow/dags/etl_to_snowflake.py","logger":"airflow.models.dagbag.DagBag"}
{"timestamp":"2025-07-23T22:03:12.364008","level":"info","event":"Snowflake Connector for Python Version: 3.16.0, Python Version: 3.12.11, Platform: Linux-5.15.167.4-microsoft-standard-WSL2-x86_64-with-glibc2.36","logger":"snowflake.connector.connection"}
{"timestamp":"2025-07-23T22:03:12.365105","level":"info","event":"Connecting to GLOBAL Snowflake domain","logger":"snowflake.connector.connection"}
{"timestamp":"2025-07-23T22:04:15.662461","level":"warning","event":"Retrying (Retry(total=0, connect=None, read=None, redirect=None, status=None)) after connection broken by 'NewConnectionError('<snowflake.connector.vendored.urllib3.connection.HTTPSConnection object at 0x7ff0e05eafc0>: Failed to establish a new connection: [Errno 111] Connection refused')': /session/v1/login-request?request_id=1394deb9-a73c-4973-b57f-8d248d5a08a9&databaseName=AIRFLOW_PIPELINE&schemaName=PUBLIC&warehouse=COMPUTE_WH&request_guid=6bdbdd21-7909-4e58-abb0-467812228157","logger":"snowflake.connector.vendored.urllib3.connectionpool"}
{"timestamp":"2025-07-23T22:05:19.000568","level":"error","event":"Task failed with exception","logger":"task","error_detail":[{"exc_type":"OperationalError","exc_value":"250001: 250001: Could not connect to Snowflake backend after 1 attempt(s).Aborting","exc_notes":[],"syntax_error":null,"is_cause":false,"frames":[{"filename":"/home/airflow/.local/lib/python3.12/site-packages/airflow/sdk/execution_time/task_runner.py","lineno":877,"name":"run"},{"filename":"/home/airflow/.local/lib/python3.12/site-packages/airflow/sdk/execution_time/task_runner.py","lineno":1164,"name":"_execute_task"},{"filename":"/home/airflow/.local/lib/python3.12/site-packages/airflow/sdk/bases/operator.py","lineno":397,"name":"wrapper"},{"filename":"/home/airflow/.local/lib/python3.12/site-packages/airflow/providers/standard/operators/python.py","lineno":217,"name":"execute"},{"filename":"/home/airflow/.local/lib/python3.12/site-packages/airflow/providers/standard/operators/python.py","lineno":240,"name":"execute_callable"},{"filename":"/home/airflow/.local/lib/python3.12/site-packages/airflow/sdk/execution_time/callback_runner.py","lineno":81,"name":"run"},{"filename":"/opt/airflow/app/shop/extract_csv.py","lineno":10,"name":"extract_csv"},{"filename":"/opt/airflow/utils/snowflake_uploader.py","lineno":8,"name":"upload_to_snowflake"},{"filename":"/home/airflow/.local/lib/python3.12/site-packages/snowflake/connector/__init__.py","lineno":54,"name":"Connect"},{"filename":"/home/airflow/.local/lib/python3.12/site-packages/snowflake/connector/connection.py","lineno":554,"name":"__init__"},{"filename":"/home/airflow/.local/lib/python3.12/site-packages/snowflake/connector/connection.py","lineno":911,"name":"connect"},{"filename":"/home/airflow/.local/lib/python3.12/site-packages/snowflake/connector/connection.py","lineno":1312,"name":"__open_connection"},{"filename":"/home/airflow/.local/lib/python3.12/site-packages/snowflake/connector/connection.py","lineno":1637,"name":"authenticate_with_retry"},{"filename":"/home/airflow/.local/lib/python3.12/site-packages/snowflake/connector/connection.py","lineno":1715,"name":"_authenticate"},{"filename":"/home/airflow/.local/lib/python3.12/site-packages/snowflake/connector/connection.py","lineno":1690,"name":"_authenticate"},{"filename":"/home/airflow/.local/lib/python3.12/site-packages/snowflake/connector/auth/by_plugin.py","lineno":212,"name":"handle_timeout"}],"is_group":false,"exceptions":[]},{"exc_type":"OperationalError","exc_value":"251011: 251011: ConnectionTimeout occurred during login. Will be handled by authenticator","exc_notes":[],"syntax_error":null,"is_cause":true,"frames":[{"filename":"/home/airflow/.local/lib/python3.12/site-packages/snowflake/connector/connection.py","lineno":1669,"name":"_authenticate"},{"filename":"/home/airflow/.local/lib/python3.12/site-packages/snowflake/connector/auth/_auth.py","lineno":226,"name":"authenticate"},{"filename":"/home/airflow/.local/lib/python3.12/site-packages/snowflake/connector/network.py","lineno":805,"name":"_post_request"},{"filename":"/home/airflow/.local/lib/python3.12/site-packages/snowflake/connector/network.py","lineno":924,"name":"fetch"},{"filename":"/home/airflow/.local/lib/python3.12/site-packages/snowflake/connector/network.py","lineno":1054,"name":"_request_exec_wrapper"},{"filename":"/home/airflow/.local/lib/python3.12/site-packages/snowflake/connector/network.py","lineno":975,"name":"_request_exec_wrapper"},{"filename":"/home/airflow/.local/lib/python3.12/site-packages/snowflake/connector/network.py","lineno":1247,"name":"_request_exec"}],"is_group":false,"exceptions":[]},{"exc_type":"ConnectionError","exc_value":"HTTPSConnectionPool(host='pc20898.snowflakecomputing.com', port=443): Max retries exceeded with url: /session/v1/login-request?request_id=1394deb9-a73c-4973-b57f-8d248d5a08a9&databaseName=AIRFLOW_PIPELINE&schemaName=PUBLIC&warehouse=COMPUTE_WH&request_guid=6bdbdd21-7909-4e58-abb0-467812228157 (Caused by NewConnectionError('<snowflake.connector.vendored.urllib3.connection.HTTPSConnection object at 0x7ff0e00b0e00>: Failed to establish a new connection: [Errno 111] Connection refused'))","exc_notes":[],"syntax_error":null,"is_cause":false,"frames":[{"filename":"/home/airflow/.local/lib/python3.12/site-packages/snowflake/connector/network.py","lineno":1149,"name":"_request_exec"},{"filename":"/home/airflow/.local/lib/python3.12/site-packages/snowflake/connector/vendored/requests/sessions.py","lineno":589,"name":"request"},{"filename":"/home/airflow/.local/lib/python3.12/site-packages/snowflake/connector/vendored/requests/sessions.py","lineno":703,"name":"send"},{"filename":"/home/airflow/.local/lib/python3.12/site-packages/snowflake/connector/vendored/requests/adapters.py","lineno":518,"name":"send"}],"is_group":false,"exceptions":[]},{"exc_type":"MaxRetryError","exc_value":"HTTPSConnectionPool(host='pc20898.snowflakecomputing.com', port=443): Max retries exceeded with url: /session/v1/login-request?request_id=1394deb9-a73c-4973-b57f-8d248d5a08a9&databaseName=AIRFLOW_PIPELINE&schemaName=PUBLIC&warehouse=COMPUTE_WH&request_guid=6bdbdd21-7909-4e58-abb0-467812228157 (Caused by NewConnectionError('<snowflake.connector.vendored.urllib3.connection.HTTPSConnection object at 0x7ff0e00b0e00>: Failed to establish a new connection: [Errno 111] Connection refused'))","exc_notes":[],"syntax_error":null,"is_cause":false,"frames":[{"filename":"/home/airflow/.local/lib/python3.12/site-packages/snowflake/connector/vendored/requests/adapters.py","lineno":485,"name":"send"},{"filename":"/home/airflow/.local/lib/python3.12/site-packages/snowflake/connector/vendored/urllib3/connectionpool.py","lineno":827,"name":"urlopen"},{"filename":"/home/airflow/.local/lib/python3.12/site-packages/snowflake/connector/vendored/urllib3/connectionpool.py","lineno":799,"name":"urlopen"},{"filename":"/home/airflow/.local/lib/python3.12/site-packages/snowflake/connector/vendored/urllib3/util/retry.py","lineno":592,"name":"increment"}],"is_group":false,"exceptions":[]},{"exc_type":"NewConnectionError","exc_value":"<snowflake.connector.vendored.urllib3.connection.HTTPSConnection object at 0x7ff0e00b0e00>: Failed to establish a new connection: [Errno 111] Connection refused","exc_notes":[],"syntax_error":null,"is_cause":false,"frames":[{"filename":"/home/airflow/.local/lib/python3.12/site-packages/snowflake/connector/vendored/urllib3/connectionpool.py","lineno":715,"name":"urlopen"},{"filename":"/home/airflow/.local/lib/python3.12/site-packages/snowflake/connector/vendored/urllib3/connectionpool.py","lineno":404,"name":"_make_request"},{"filename":"/home/airflow/.local/lib/python3.12/site-packages/snowflake/connector/vendored/urllib3/connectionpool.py","lineno":1058,"name":"_validate_conn"},{"filename":"/home/airflow/.local/lib/python3.12/site-packages/snowflake/connector/vendored/urllib3/connection.py","lineno":363,"name":"connect"},{"filename":"/home/airflow/.local/lib/python3.12/site-packages/snowflake/connector/vendored/urllib3/connection.py","lineno":186,"name":"_new_conn"}],"is_group":false,"exceptions":[]},{"exc_type":"ConnectionRefusedError","exc_value":"[Errno 111] Connection refused","exc_notes":[],"syntax_error":null,"is_cause":false,"frames":[{"filename":"/home/airflow/.local/lib/python3.12/site-packages/snowflake/connector/vendored/urllib3/connection.py","lineno":174,"name":"_new_conn"},{"filename":"/home/airflow/.local/lib/python3.12/site-packages/snowflake/connector/vendored/urllib3/util/connection.py","lineno":102,"name":"create_connection"},{"filename":"/home/airflow/.local/lib/python3.12/site-packages/snowflake/connector/vendored/urllib3/util/connection.py","lineno":92,"name":"create_connection"}],"is_group":false,"exceptions":[]}]}
