{"timestamp":"2025-07-23T22:00:20.681698","level":"info","event":"DAG bundles loaded: dags-folder","logger":"airflow.dag_processing.bundles.manager.DagBundlesManager"}
{"timestamp":"2025-07-23T22:00:20.682746","level":"info","event":"Filling up the DagBag from /opt/airflow/dags/etl_to_snowflake.py","logger":"airflow.models.dagbag.DagBag"}
{"timestamp":"2025-07-23T22:00:22.175774","level":"info","event":"Snowflake Connector for Python Version: 3.16.0, Python Version: 3.12.11, Platform: Linux-5.15.167.4-microsoft-standard-WSL2-x86_64-with-glibc2.36","logger":"snowflake.connector.connection"}
{"timestamp":"2025-07-23T22:00:22.177166","level":"info","event":"Connecting to GLOBAL Snowflake domain","logger":"snowflake.connector.connection"}
{"timestamp":"2025-07-23T22:01:25.302133","level":"warning","event":"Retrying (Retry(total=0, connect=None, read=None, redirect=None, status=None)) after connection broken by 'NewConnectionError('<snowflake.connector.vendored.urllib3.connection.HTTPSConnection object at 0x7fc1a51dc350>: Failed to establish a new connection: [Errno 111] Connection refused')': /session/v1/login-request?request_id=98a20ae4-bd71-4ff9-9b2f-0bc2846608d8&databaseName=AIRFLOW_PIPELINE&schemaName=PUBLIC&warehouse=COMPUTE_WH&request_guid=a78d0905-da97-44f6-a47b-45d0ea42beab","logger":"snowflake.connector.vendored.urllib3.connectionpool"}
