{"timestamp":"2025-07-23T22:00:18.028694","level":"info","event":"DAG bundles loaded: dags-folder","logger":"airflow.dag_processing.bundles.manager.DagBundlesManager"}
{"timestamp":"2025-07-23T22:00:18.029432","level":"info","event":"Filling up the DagBag from /opt/airflow/dags/etl_to_snowflake.py","logger":"airflow.models.dagbag.DagBag"}
{"timestamp":"2025-07-23T22:00:20.290955","level":"info","event":"Snowflake Connector for Python Version: 3.16.0, Python Version: 3.12.11, Platform: Linux-5.15.167.4-microsoft-standard-WSL2-x86_64-with-glibc2.36","logger":"snowflake.connector.connection"}
{"timestamp":"2025-07-23T22:00:20.291983","level":"info","event":"Connecting to GLOBAL Snowflake domain","logger":"snowflake.connector.connection"}
{"timestamp":"2025-07-23T22:01:23.660574","level":"warning","event":"Retrying (Retry(total=0, connect=None, read=None, redirect=None, status=None)) after connection broken by 'NewConnectionError('<snowflake.connector.vendored.urllib3.connection.HTTPSConnection object at 0x7fc1a240b590>: Failed to establish a new connection: [Errno 111] Connection refused')': /session/v1/login-request?request_id=b63b0bcf-e134-460c-934a-1810e14b5b92&databaseName=AIRFLOW_PIPELINE&schemaName=PUBLIC&warehouse=COMPUTE_WH&request_guid=2f609cbf-1c18-4f2f-bb9f-647c86666235","logger":"snowflake.connector.vendored.urllib3.connectionpool"}
